Failure # 1 (occurred at 2022-08-12_10-52-23)
Traceback (most recent call last):
  File "/home/xwm/anaconda3/envs/SV/lib/python3.6/site-packages/ray/tune/trial_runner.py", line 886, in _process_trial
    results = self.trial_executor.fetch_result(trial)
  File "/home/xwm/anaconda3/envs/SV/lib/python3.6/site-packages/ray/tune/ray_trial_executor.py", line 675, in fetch_result
    result = ray.get(trial_future[0], timeout=DEFAULT_GET_TIMEOUT)
  File "/home/xwm/anaconda3/envs/SV/lib/python3.6/site-packages/ray/_private/client_mode_hook.py", line 105, in wrapper
    return func(*args, **kwargs)
  File "/home/xwm/anaconda3/envs/SV/lib/python3.6/site-packages/ray/worker.py", line 1763, in get
    raise value.as_instanceof_cause()
ray.exceptions.RayTaskError(TuneError): [36mray::ImplicitFunc.train()[39m (pid=86243, ip=192.168.249.74, repr=train_tune)
  File "/home/xwm/anaconda3/envs/SV/lib/python3.6/site-packages/ray/tune/trainable.py", line 319, in train
    result = self.step()
  File "/home/xwm/anaconda3/envs/SV/lib/python3.6/site-packages/ray/tune/function_runner.py", line 381, in step
    self._report_thread_runner_error(block=True)
  File "/home/xwm/anaconda3/envs/SV/lib/python3.6/site-packages/ray/tune/function_runner.py", line 532, in _report_thread_runner_error
    ("Trial raised an exception. Traceback:\n{}".format(err_tb_str)
ray.tune.error.TuneError: Trial raised an exception. Traceback:
[36mray::ImplicitFunc.train()[39m (pid=86243, ip=192.168.249.74, repr=train_tune)
  File "/home/xwm/anaconda3/envs/SV/lib/python3.6/site-packages/ray/tune/function_runner.py", line 262, in run
    self._entrypoint()
  File "/home/xwm/anaconda3/envs/SV/lib/python3.6/site-packages/ray/tune/function_runner.py", line 331, in entrypoint
    self._status_reporter.get_checkpoint())
  File "/home/xwm/anaconda3/envs/SV/lib/python3.6/site-packages/ray/tune/function_runner.py", line 600, in _trainable_func
    output = fn()
  File "/home/xwm/anaconda3/envs/SV/lib/python3.6/site-packages/ray/tune/utils/trainable.py", line 371, in inner
    trainable(config, **fn_kwargs)
  File "train.py", line 114, in train_tune
    trainer.fit(model)
  File "/home/xwm/anaconda3/envs/SV/lib/python3.6/site-packages/pytorch_lightning/trainer/trainer.py", line 741, in fit
    self._fit_impl, model, train_dataloaders, val_dataloaders, datamodule, ckpt_path
  File "/home/xwm/anaconda3/envs/SV/lib/python3.6/site-packages/pytorch_lightning/trainer/trainer.py", line 685, in _call_and_handle_interrupt
    return trainer_fn(*args, **kwargs)
  File "/home/xwm/anaconda3/envs/SV/lib/python3.6/site-packages/pytorch_lightning/trainer/trainer.py", line 777, in _fit_impl
    self._run(model, ckpt_path=ckpt_path)
  File "/home/xwm/anaconda3/envs/SV/lib/python3.6/site-packages/pytorch_lightning/trainer/trainer.py", line 1199, in _run
    self._dispatch()
  File "/home/xwm/anaconda3/envs/SV/lib/python3.6/site-packages/pytorch_lightning/trainer/trainer.py", line 1279, in _dispatch
    self.training_type_plugin.start_training(self)
  File "/home/xwm/anaconda3/envs/SV/lib/python3.6/site-packages/pytorch_lightning/plugins/training_type/training_type_plugin.py", line 202, in start_training
    self._results = trainer.run_stage()
  File "/home/xwm/anaconda3/envs/SV/lib/python3.6/site-packages/pytorch_lightning/trainer/trainer.py", line 1289, in run_stage
    return self._run_train()
  File "/home/xwm/anaconda3/envs/SV/lib/python3.6/site-packages/pytorch_lightning/trainer/trainer.py", line 1311, in _run_train
    self._run_sanity_check(self.lightning_module)
  File "/home/xwm/anaconda3/envs/SV/lib/python3.6/site-packages/pytorch_lightning/trainer/trainer.py", line 1375, in _run_sanity_check
    self._evaluation_loop.run()
  File "/home/xwm/anaconda3/envs/SV/lib/python3.6/site-packages/pytorch_lightning/loops/base.py", line 145, in run
    self.advance(*args, **kwargs)
  File "/home/xwm/anaconda3/envs/SV/lib/python3.6/site-packages/pytorch_lightning/loops/dataloader/evaluation_loop.py", line 110, in advance
    dl_outputs = self.epoch_loop.run(dataloader, dataloader_idx, dl_max_batches, self.num_dataloaders)
  File "/home/xwm/anaconda3/envs/SV/lib/python3.6/site-packages/pytorch_lightning/loops/base.py", line 145, in run
    self.advance(*args, **kwargs)
  File "/home/xwm/anaconda3/envs/SV/lib/python3.6/site-packages/pytorch_lightning/loops/epoch/evaluation_epoch_loop.py", line 122, in advance
    output = self._evaluation_step(batch, batch_idx, dataloader_idx)
  File "/home/xwm/anaconda3/envs/SV/lib/python3.6/site-packages/pytorch_lightning/loops/epoch/evaluation_epoch_loop.py", line 217, in _evaluation_step
    output = self.trainer.accelerator.validation_step(step_kwargs)
  File "/home/xwm/anaconda3/envs/SV/lib/python3.6/site-packages/pytorch_lightning/accelerators/accelerator.py", line 239, in validation_step
    return self.training_type_plugin.validation_step(*step_kwargs.values())
  File "/home/xwm/anaconda3/envs/SV/lib/python3.6/site-packages/pytorch_lightning/plugins/training_type/training_type_plugin.py", line 219, in validation_step
    return self.model.validation_step(*args, **kwargs)
  File "/home/xwm/DeepSVFilter/code_BIBM/net.py", line 218, in validation_step
    loss, y, y_hat = self.training_validation_step(batch, batch_idx)
  File "/home/xwm/DeepSVFilter/code_BIBM/net.py", line 150, in training_validation_step
    x = self.conv2ds(x)
  File "/home/xwm/anaconda3/envs/SV/lib/python3.6/site-packages/torch/nn/modules/module.py", line 1102, in _call_impl
    return forward_call(*input, **kwargs)
  File "/home/xwm/DeepSVFilter/code_BIBM/net.py", line 82, in forward
    out=layer(out)
  File "/home/xwm/anaconda3/envs/SV/lib/python3.6/site-packages/torch/nn/modules/module.py", line 1102, in _call_impl
    return forward_call(*input, **kwargs)
  File "/home/xwm/anaconda3/envs/SV/lib/python3.6/site-packages/torch/nn/modules/container.py", line 141, in forward
    input = module(input)
  File "/home/xwm/anaconda3/envs/SV/lib/python3.6/site-packages/torch/nn/modules/module.py", line 1102, in _call_impl
    return forward_call(*input, **kwargs)
  File "/home/xwm/anaconda3/envs/SV/lib/python3.6/site-packages/torch/nn/modules/conv.py", line 446, in forward
    return self._conv_forward(input, self.weight, self.bias)
  File "/home/xwm/anaconda3/envs/SV/lib/python3.6/site-packages/torch/nn/modules/conv.py", line 443, in _conv_forward
    self.padding, self.dilation, self.groups)
RuntimeError: Given groups=1, weight of size [4, 4, 3, 3], expected input[64, 5, 224, 224] to have 4 channels, but got 5 channels instead

